3.6
An error occurred while executing the following cell:
------------------
import warnings
warnings.filterwarnings('ignore')
import numpy as np
import pandas as pd
import matplotlib.pyplot as plt
import seaborn as sns
%matplotlib inline
from pandas_datareader import data as wb
------------------

[0;31m---------------------------------------------------------------------------[0m
[0;31mModuleNotFoundError[0m                       Traceback (most recent call last)
[0;32m<ipython-input-1-6df8cf29b818>[0m in [0;36m<module>[0;34m[0m
[1;32m      6[0m [0;32mimport[0m [0mseaborn[0m [0;32mas[0m [0msns[0m[0;34m[0m[0;34m[0m[0m
[1;32m      7[0m [0mget_ipython[0m[0;34m([0m[0;34m)[0m[0;34m.[0m[0mrun_line_magic[0m[0;34m([0m[0;34m'matplotlib'[0m[0;34m,[0m [0;34m'inline'[0m[0;34m)[0m[0;34m[0m[0;34m[0m[0m
[0;32m----> 8[0;31m [0;32mfrom[0m [0mpandas_datareader[0m [0;32mimport[0m [0mdata[0m [0;32mas[0m [0mwb[0m[0;34m[0m[0;34m[0m[0m
[0m
[0;31mModuleNotFoundError[0m: No module named 'pandas_datareader'
ModuleNotFoundError: No module named 'pandas_datareader'

Executability                            : False
