3.6
An error occurred while executing the following cell:
------------------
import warnings
warnings.filterwarnings('ignore')
data = pd.read_csv('pokemon-challenge/pokemon.csv')
print (data.info())
------------------

[0;31m---------------------------------------------------------------------------[0m
[0;31mNameError[0m                                 Traceback (most recent call last)
[0;32m<ipython-input-1-ae977c44dd69>[0m in [0;36m<module>[0;34m[0m
[1;32m      1[0m [0;32mimport[0m [0mwarnings[0m[0;34m[0m[0;34m[0m[0m
[1;32m      2[0m [0mwarnings[0m[0;34m.[0m[0mfilterwarnings[0m[0;34m([0m[0;34m'ignore'[0m[0;34m)[0m[0;34m[0m[0;34m[0m[0m
[0;32m----> 3[0;31m [0mdata[0m [0;34m=[0m [0mpd[0m[0;34m.[0m[0mread_csv[0m[0;34m([0m[0;34m'pokemon-challenge/pokemon.csv'[0m[0;34m)[0m[0;34m[0m[0;34m[0m[0m
[0m[1;32m      4[0m [0mprint[0m [0;34m([0m[0mdata[0m[0;34m.[0m[0minfo[0m[0;34m([0m[0;34m)[0m[0;34m)[0m[0;34m[0m[0;34m[0m[0m

[0;31mNameError[0m: name 'pd' is not defined
NameError: name 'pd' is not defined

Executability                            : False
