3.5
An error occurred while executing the following cell:
------------------
import warnings
warnings.filterwarnings('ignore')
import numpy                    as np
import pandas                   as pd
import sklearn.cross_validation as cv
import matplotlib.pyplot        as plt

from sklearn.ensemble import GradientBoostingClassifier
from sklearn.ensemble import RandomForestClassifier
from sklearn.metrics  import log_loss

%matplotlib inline
------------------

[0;31m---------------------------------------------------------------------------[0m
[0;31mImportError[0m                               Traceback (most recent call last)
[0;32m<ipython-input-1-2450864ae5cd>[0m in [0;36m<module>[0;34m()[0m
[1;32m      3[0m [0;32mimport[0m [0mnumpy[0m                    [0;32mas[0m [0mnp[0m[0;34m[0m[0m
[1;32m      4[0m [0;32mimport[0m [0mpandas[0m                   [0;32mas[0m [0mpd[0m[0;34m[0m[0m
[0;32m----> 5[0;31m [0;32mimport[0m [0msklearn[0m[0;34m.[0m[0mcross_validation[0m [0;32mas[0m [0mcv[0m[0;34m[0m[0m
[0m[1;32m      6[0m [0;32mimport[0m [0mmatplotlib[0m[0;34m.[0m[0mpyplot[0m        [0;32mas[0m [0mplt[0m[0;34m[0m[0m
[1;32m      7[0m [0;34m[0m[0m

[0;31mImportError[0m: No module named 'sklearn.cross_validation'
ImportError: No module named 'sklearn.cross_validation'

Executability                            : False
