3.6
An error occurred while executing the following cell:
------------------
# Load pickled data
training_file ="traffic-signs-data/train.p"
validation_file="traffic-signs-data/valid.p"
testing_file = "traffic-signs-data/test.p"

with open(training_file, mode='rb') as f:
    train = pickle.load(f)
with open(validation_file, mode='rb') as f:
    valid = pickle.load(f)
with open(testing_file, mode='rb') as f:
    test = pickle.load(f)
    
X_train, y_train = train['features'], train['labels']
X_valid, y_valid = valid['features'], valid['labels']
X_test, y_test = test['features'], test['labels']
------------------

[0;31m---------------------------------------------------------------------------[0m
[0;31mFileNotFoundError[0m                         Traceback (most recent call last)
[0;32m<ipython-input-2-a9a20a7fb27f>[0m in [0;36m<module>[0;34m[0m
[1;32m      4[0m [0mtesting_file[0m [0;34m=[0m [0;34m"traffic-signs-data/test.p"[0m[0;34m[0m[0;34m[0m[0m
[1;32m      5[0m [0;34m[0m[0m
[0;32m----> 6[0;31m [0;32mwith[0m [0mopen[0m[0;34m([0m[0mtraining_file[0m[0;34m,[0m [0mmode[0m[0;34m=[0m[0;34m'rb'[0m[0;34m)[0m [0;32mas[0m [0mf[0m[0;34m:[0m[0;34m[0m[0;34m[0m[0m
[0m[1;32m      7[0m     [0mtrain[0m [0;34m=[0m [0mpickle[0m[0;34m.[0m[0mload[0m[0;34m([0m[0mf[0m[0;34m)[0m[0;34m[0m[0;34m[0m[0m
[1;32m      8[0m [0;32mwith[0m [0mopen[0m[0;34m([0m[0mvalidation_file[0m[0;34m,[0m [0mmode[0m[0;34m=[0m[0;34m'rb'[0m[0;34m)[0m [0;32mas[0m [0mf[0m[0;34m:[0m[0;34m[0m[0;34m[0m[0m

[0;31mFileNotFoundError[0m: [Errno 2] No such file or directory: 'traffic-signs-data/train.p'
FileNotFoundError: [Errno 2] No such file or directory: 'traffic-signs-data/train.p'

Executability                            : False
